2018-05-22 10:01:43,879 - root - ERROR - __init__: 
Traceback (most recent call last):
  File "D:/SW/BigData_AI/MyProject/1. RecommendationEngine_04122018/Product/2. P1_Prepare/exploratory_data_analysis/scripts/exploratory_data_analysis.py", line 23, in get_config_info
    self.logger.info('ExploratoryDataAnalysis:get_config_info')
AttributeError: 'ExploratoryDataAnalysis' object has no attribute 'logger'

During handling of the above exception, another exception occurred:

Traceback (most recent call last):
  File "D:/SW/BigData_AI/MyProject/1. RecommendationEngine_04122018/Product/2. P1_Prepare/exploratory_data_analysis/scripts/exploratory_data_analysis.py", line 15, in main
    eda.get_config_info()
  File "D:/SW/BigData_AI/MyProject/1. RecommendationEngine_04122018/Product/2. P1_Prepare/exploratory_data_analysis/scripts/exploratory_data_analysis.py", line 30, in get_config_info
    self.logger.error('get_config_info', exc_info = True)
AttributeError: 'ExploratoryDataAnalysis' object has no attribute 'logger'
2018-05-22 10:05:24,057 - root - ERROR - __init__: 
Traceback (most recent call last):
  File "D:/SW/BigData_AI/MyProject/1. RecommendationEngine_04122018/Product/2. P1_Prepare/exploratory_data_analysis/scripts/exploratory_data_analysis.py", line 15, in main
    eda.get_config_info(logger)
TypeError: get_config_info() takes 1 positional argument but 2 were given
2018-05-22 10:10:09,114 - root - ERROR - __init__: 
Traceback (most recent call last):
  File "D:/SW/BigData_AI/MyProject/1. RecommendationEngine_04122018/Product/2. P1_Prepare/exploratory_data_analysis/scripts/exploratory_data_analysis.py", line 15, in main
    eda.get_config_info()
TypeError: get_config_info() takes 0 positional arguments but 1 was given
2018-05-22 10:22:43,234 - root - ERROR - get_config_info
Traceback (most recent call last):
  File "D:/SW/BigData_AI/MyProject/1. RecommendationEngine_04122018/Product/2. P1_Prepare/exploratory_data_analysis/scripts/exploratory_data_analysis.py", line 30, in get_config_info
    ds._calulate_descriptive_statistics(path)
  File "D:\SW\BigData_AI\MyProject\1. RecommendationEngine_04122018\Product\2. P1_Prepare\exploratory_data_analysis\scripts\descriptive_statistics.py", line 11, in _calulate_descriptive_statistics
    logger.info('DescriptiveStatistics:_calulate_descriptive_statistics')
AttributeError: 'str' object has no attribute 'info'
